<?xml version="1.0" ?>
<!-- Generated using onshape-to-robot -->
<!-- Onshape https://cad.onshape.com/documents/d45957d307d6fbeba266d572/w/bd9f549c3008356ba09feb92/e/3a20e3144e899f6462cf0d2d -->
<robot name="my-robot">
  <!-- Link bottom_frame -->
  <link name="bottom_frame">
    <inertial>
      <origin xyz="-4.22758e-05 0.031606 0.133755" rpy="0 0 0"/>
      <mass value="1.98264"/>
      <inertia ixx="0.0231085" ixy="-1.50349e-05" ixz="-6.98111e-06" iyy="0.0159689" iyz="2.79408e-05" izz="0.0181058"/>
    </inertial>
    <!-- Part back_middle_connector_panel -->
    <visual>
      <origin xyz="1.38778e-17 0.0155347 0.132536" rpy="0 -0 1.47801e-16"/>
      <geometry>
        <mesh filename="package://assets/back_middle_connector_panel.stl"/>
      </geometry>
      <material name="back_middle_connector_panel_material">
        <color rgba="0.917647 0.917647 0.917647 1"/>
      </material>
    </visual>
    <collision>
      <origin xyz="1.38778e-17 0.0155347 0.132536" rpy="0 -0 1.47801e-16"/>
      <geometry>
        <mesh filename="package://assets/back_middle_connector_panel.stl"/>
      </geometry>
    </collision>
    <!-- Part top_right_panel_2 -->
    <visual>
      <origin xyz="0 -0.0931549 0.132536" rpy="0 -0 0"/>
      <geometry>
        <mesh filename="package://assets/top_right_panel_2.stl"/>
      </geometry>
      <material name="top_right_panel_2_material">
        <color rgba="0.917647 0.917647 0.917647 1"/>
      </material>
    </visual>
    <collision>
      <origin xyz="0 -0.0931549 0.132536" rpy="0 -0 0"/>
      <geometry>
        <mesh filename="package://assets/top_right_panel_2.stl"/>
      </geometry>
    </collision>
    <!-- Part top_left_panel -->
    <visual>
      <origin xyz="-1.38778e-17 -0.0931549 0.132536" rpy="0 -0 0"/>
      <geometry>
        <mesh filename="package://assets/top_left_panel.stl"/>
      </geometry>
      <material name="top_left_panel_material">
        <color rgba="0.917647 0.917647 0.917647 1"/>
      </material>
    </visual>
    <collision>
      <origin xyz="-1.38778e-17 -0.0931549 0.132536" rpy="0 -0 0"/>
      <geometry>
        <mesh filename="package://assets/top_left_panel.stl"/>
      </geometry>
    </collision>
    <!-- Part servo_housing_connector -->
    <visual>
      <origin xyz="0.0505 0.0285376 0.124733" rpy="0 -0 0"/>
      <geometry>
        <mesh filename="package://assets/servo_housing_connector.stl"/>
      </geometry>
      <material name="servo_housing_connector_material">
        <color rgba="0.917647 0.917647 0.917647 1"/>
      </material>
    </visual>
    <collision>
      <origin xyz="0.0505 0.0285376 0.124733" rpy="0 -0 0"/>
      <geometry>
        <mesh filename="package://assets/servo_housing_connector.stl"/>
      </geometry>
    </collision>
    <!-- Part front_panel -->
    <visual>
      <origin xyz="-1.38778e-17 -0.0931549 0.132536" rpy="0 -0 0"/>
      <geometry>
        <mesh filename="package://assets/front_panel.stl"/>
      </geometry>
      <material name="front_panel_material">
        <color rgba="0.917647 0.917647 0.917647 1"/>
      </material>
    </visual>
    <collision>
      <origin xyz="-1.38778e-17 -0.0931549 0.132536" rpy="0 -0 0"/>
      <geometry>
        <mesh filename="package://assets/front_panel.stl"/>
      </geometry>
    </collision>
    <!-- Part top_servo_housing -->
    <visual>
      <origin xyz="-0.0505 0.0285376 0.124733" rpy="3.14159 -0 3.14159"/>
      <geometry>
        <mesh filename="package://assets/top_servo_housing.stl"/>
      </geometry>
      <material name="top_servo_housing_material">
        <color rgba="0.231373 0.380392 0.705882 1"/>
      </material>
    </visual>
    <collision>
      <origin xyz="-0.0505 0.0285376 0.124733" rpy="3.14159 -0 3.14159"/>
      <geometry>
        <mesh filename="package://assets/top_servo_housing.stl"/>
      </geometry>
    </collision>
    <!-- Part intelrealsense_d435_multibody -->
    <visual>
      <origin xyz="-5.56425e-18 -0.0955775 0.170421" rpy="1.8326 -0 0"/>
      <geometry>
        <mesh filename="package://assets/intelrealsense_d435_multibody.stl"/>
      </geometry>
      <material name="intelrealsense_d435_multibody_material">
        <color rgba="0.917647 0.917647 0.917647 1"/>
      </material>
    </visual>
    <collision>
      <origin xyz="-5.56425e-18 -0.0955775 0.170421" rpy="1.8326 -0 0"/>
      <geometry>
        <mesh filename="package://assets/intelrealsense_d435_multibody.stl"/>
      </geometry>
    </collision>
    <!-- Part servo_holder_left -->
    <visual>
      <origin xyz="-0.0505 0.0285376 0.124733" rpy="3.14159 -9.86076e-32 3.14159"/>
      <geometry>
        <mesh filename="package://assets/servo_holder_left.stl"/>
      </geometry>
      <material name="servo_holder_left_material">
        <color rgba="0.647059 0.647059 0.647059 1"/>
      </material>
    </visual>
    <collision>
      <origin xyz="-0.0505 0.0285376 0.124733" rpy="3.14159 -9.86076e-32 3.14159"/>
      <geometry>
        <mesh filename="package://assets/servo_holder_left.stl"/>
      </geometry>
    </collision>
    <!-- Part bottom_frame -->
    <visual>
      <origin xyz="0 0 0" rpy="0 -0 0"/>
      <geometry>
        <mesh filename="package://assets/bottom_frame.stl"/>
      </geometry>
      <material name="bottom_frame_material">
        <color rgba="0.917647 0.917647 0.917647 1"/>
      </material>
    </visual>
    <collision>
      <origin xyz="0 0 0" rpy="0 -0 0"/>
      <geometry>
        <mesh filename="package://assets/bottom_frame.stl"/>
      </geometry>
    </collision>
    <!-- Part servo_holder_right -->
    <visual>
      <origin xyz="-0.0505 0.0285376 0.124733" rpy="3.14159 -9.86076e-32 3.14159"/>
      <geometry>
        <mesh filename="package://assets/servo_holder_right.stl"/>
      </geometry>
      <material name="servo_holder_right_material">
        <color rgba="0.647059 0.647059 0.647059 1"/>
      </material>
    </visual>
    <collision>
      <origin xyz="-0.0505 0.0285376 0.124733" rpy="3.14159 -9.86076e-32 3.14159"/>
      <geometry>
        <mesh filename="package://assets/servo_holder_right.stl"/>
      </geometry>
    </collision>
    <!-- Part composant4 -->
    <visual>
      <origin xyz="0.0505 0.0162713 0.124733" rpy="3.14159 -0 -1.5708"/>
      <geometry>
        <mesh filename="package://assets/composant4.stl"/>
      </geometry>
      <material name="composant4_material">
        <color rgba="0.952941 0.796078 0.486275 1"/>
      </material>
    </visual>
    <collision>
      <origin xyz="0.0505 0.0162713 0.124733" rpy="3.14159 -0 -1.5708"/>
      <geometry>
        <mesh filename="package://assets/composant4.stl"/>
      </geometry>
    </collision>
    <!-- Part vis_à_tête_tronconique_jis_b_1111___m3_x_4___h_acier_inoxydable_a2_standard_v1 -->
    <visual>
      <origin xyz="0.0505 0.0162713 0.124733" rpy="3.14159 -0 -1.5708"/>
      <geometry>
        <mesh filename="package://assets/vis_à_tête_tronconique_jis_b_1111___m3_x_4___h_acier_inoxydable_a2_standard_v1.stl"/>
      </geometry>
      <material name="vis_à_tête_tronconique_jis_b_1111___m3_x_4___h_acier_inoxydable_a2_standard_v1_material">
        <color rgba="0.796078 0.796078 0.796078 1"/>
      </material>
    </visual>
    <collision>
      <origin xyz="0.0505 0.0162713 0.124733" rpy="3.14159 -0 -1.5708"/>
      <geometry>
        <mesh filename="package://assets/vis_à_tête_tronconique_jis_b_1111___m3_x_4___h_acier_inoxydable_a2_standard_v1.stl"/>
      </geometry>
    </collision>
    <!-- Part vis -->
    <visual>
      <origin xyz="0.0505 0.0162713 0.124733" rpy="3.14159 -0 -1.5708"/>
      <geometry>
        <mesh filename="package://assets/vis.stl"/>
      </geometry>
      <material name="vis_material">
        <color rgba="0.0980392 0.0980392 0.0980392 1"/>
      </material>
    </visual>
    <collision>
      <origin xyz="0.0505 0.0162713 0.124733" rpy="3.14159 -0 -1.5708"/>
      <geometry>
        <mesh filename="package://assets/vis.stl"/>
      </geometry>
    </collision>
    <!-- Part composant3 -->
    <visual>
      <origin xyz="0.0505 0.0162713 0.124733" rpy="3.14159 -0 -1.5708"/>
      <geometry>
        <mesh filename="package://assets/composant3.stl"/>
      </geometry>
      <material name="composant3_material">
        <color rgba="0.960784 0.960784 0.964706 1"/>
      </material>
    </visual>
    <collision>
      <origin xyz="0.0505 0.0162713 0.124733" rpy="3.14159 -0 -1.5708"/>
      <geometry>
        <mesh filename="package://assets/composant3.stl"/>
      </geometry>
    </collision>
    <!-- Part vis_1 -->
    <visual>
      <origin xyz="0.0505 0.0162713 0.124733" rpy="3.14159 -0 -1.5708"/>
      <geometry>
        <mesh filename="package://assets/vis_1.stl"/>
      </geometry>
      <material name="vis_1_material">
        <color rgba="0.0980392 0.0980392 0.0980392 1"/>
      </material>
    </visual>
    <collision>
      <origin xyz="0.0505 0.0162713 0.124733" rpy="3.14159 -0 -1.5708"/>
      <geometry>
        <mesh filename="package://assets/vis_1.stl"/>
      </geometry>
    </collision>
    <!-- Part composant2 -->
    <visual>
      <origin xyz="0.0505 0.0162713 0.124733" rpy="3.14159 -0 -1.5708"/>
      <geometry>
        <mesh filename="package://assets/composant2.stl"/>
      </geometry>
      <material name="composant2_material">
        <color rgba="0.960784 0.960784 0.964706 1"/>
      </material>
    </visual>
    <collision>
      <origin xyz="0.0505 0.0162713 0.124733" rpy="3.14159 -0 -1.5708"/>
      <geometry>
        <mesh filename="package://assets/composant2.stl"/>
      </geometry>
    </collision>
    <!-- Part servo_motor_sts3215_v10 -->
    <visual>
      <origin xyz="0.0505 0.0162713 0.124733" rpy="3.14159 -0 -1.5708"/>
      <geometry>
        <mesh filename="package://assets/servo_motor_sts3215_v10.stl"/>
      </geometry>
      <material name="servo_motor_sts3215_v10_material">
        <color rgba="0.247059 0.247059 0.247059 1"/>
      </material>
    </visual>
    <collision>
      <origin xyz="0.0505 0.0162713 0.124733" rpy="3.14159 -0 -1.5708"/>
      <geometry>
        <mesh filename="package://assets/servo_motor_sts3215_v10.stl"/>
      </geometry>
    </collision>
    <!-- Part composant4_2 -->
    <visual>
      <origin xyz="-0.0505 0.0162713 0.124733" rpy="3.14159 -0 -1.5708"/>
      <geometry>
        <mesh filename="package://assets/composant4.stl"/>
      </geometry>
      <material name="composant4_2_material">
        <color rgba="0.952941 0.796078 0.486275 1"/>
      </material>
    </visual>
    <collision>
      <origin xyz="-0.0505 0.0162713 0.124733" rpy="3.14159 -0 -1.5708"/>
      <geometry>
        <mesh filename="package://assets/composant4.stl"/>
      </geometry>
    </collision>
    <!-- Part vis_à_tête_tronconique_jis_b_1111___m3_x_4___h_acier_inoxydable_a2_standard_v1_2 -->
    <visual>
      <origin xyz="-0.0505 0.0162713 0.124733" rpy="3.14159 -0 -1.5708"/>
      <geometry>
        <mesh filename="package://assets/vis_à_tête_tronconique_jis_b_1111___m3_x_4___h_acier_inoxydable_a2_standard_v1.stl"/>
      </geometry>
      <material name="vis_à_tête_tronconique_jis_b_1111___m3_x_4___h_acier_inoxydable_a2_standard_v1_2_material">
        <color rgba="0.796078 0.796078 0.796078 1"/>
      </material>
    </visual>
    <collision>
      <origin xyz="-0.0505 0.0162713 0.124733" rpy="3.14159 -0 -1.5708"/>
      <geometry>
        <mesh filename="package://assets/vis_à_tête_tronconique_jis_b_1111___m3_x_4___h_acier_inoxydable_a2_standard_v1.stl"/>
      </geometry>
    </collision>
    <!-- Part vis_2 -->
    <visual>
      <origin xyz="-0.0505 0.0162713 0.124733" rpy="3.14159 -0 -1.5708"/>
      <geometry>
        <mesh filename="package://assets/vis.stl"/>
      </geometry>
      <material name="vis_2_material">
        <color rgba="0.0980392 0.0980392 0.0980392 1"/>
      </material>
    </visual>
    <collision>
      <origin xyz="-0.0505 0.0162713 0.124733" rpy="3.14159 -0 -1.5708"/>
      <geometry>
        <mesh filename="package://assets/vis.stl"/>
      </geometry>
    </collision>
    <!-- Part composant3_2 -->
    <visual>
      <origin xyz="-0.0505 0.0162713 0.124733" rpy="3.14159 -0 -1.5708"/>
      <geometry>
        <mesh filename="package://assets/composant3.stl"/>
      </geometry>
      <material name="composant3_2_material">
        <color rgba="0.960784 0.960784 0.964706 1"/>
      </material>
    </visual>
    <collision>
      <origin xyz="-0.0505 0.0162713 0.124733" rpy="3.14159 -0 -1.5708"/>
      <geometry>
        <mesh filename="package://assets/composant3.stl"/>
      </geometry>
    </collision>
    <!-- Part vis_1_2 -->
    <visual>
      <origin xyz="-0.0505 0.0162713 0.124733" rpy="3.14159 -0 -1.5708"/>
      <geometry>
        <mesh filename="package://assets/vis_1.stl"/>
      </geometry>
      <material name="vis_1_2_material">
        <color rgba="0.0980392 0.0980392 0.0980392 1"/>
      </material>
    </visual>
    <collision>
      <origin xyz="-0.0505 0.0162713 0.124733" rpy="3.14159 -0 -1.5708"/>
      <geometry>
        <mesh filename="package://assets/vis_1.stl"/>
      </geometry>
    </collision>
    <!-- Part composant2_2 -->
    <visual>
      <origin xyz="-0.0505 0.0162713 0.124733" rpy="3.14159 -0 -1.5708"/>
      <geometry>
        <mesh filename="package://assets/composant2.stl"/>
      </geometry>
      <material name="composant2_2_material">
        <color rgba="0.960784 0.960784 0.964706 1"/>
      </material>
    </visual>
    <collision>
      <origin xyz="-0.0505 0.0162713 0.124733" rpy="3.14159 -0 -1.5708"/>
      <geometry>
        <mesh filename="package://assets/composant2.stl"/>
      </geometry>
    </collision>
    <!-- Part servo_motor_sts3215_v10_2 -->
    <visual>
      <origin xyz="-0.0505 0.0162713 0.124733" rpy="3.14159 -0 -1.5708"/>
      <geometry>
        <mesh filename="package://assets/servo_motor_sts3215_v10.stl"/>
      </geometry>
      <material name="servo_motor_sts3215_v10_2_material">
        <color rgba="0.247059 0.247059 0.247059 1"/>
      </material>
    </visual>
    <collision>
      <origin xyz="-0.0505 0.0162713 0.124733" rpy="3.14159 -0 -1.5708"/>
      <geometry>
        <mesh filename="package://assets/servo_motor_sts3215_v10.stl"/>
      </geometry>
    </collision>
  </link>
  <!-- Link part_1 -->
  <link name="part_1">
    <inertial>
      <origin xyz="0.00346141 -1.8868e-08 0.0544996" rpy="0 0 0"/>
      <mass value="0.0633736"/>
      <inertia ixx="4.16786e-05" ixy="1.75025e-11" ixz="9.10103e-06" iyy="4.826e-05" iyz="-7.87076e-12" izz="1.32807e-05"/>
    </inertial>
    <!-- Part part_1 -->
    <visual>
      <origin xyz="4.33681e-19 0 0" rpy="3.14159 3.26186e-36 -4.9299e-32"/>
      <geometry>
        <mesh filename="package://assets/part_1.stl"/>
      </geometry>
      <material name="part_1_material">
        <color rgba="0.262745 0.282353 0.301961 1"/>
      </material>
    </visual>
    <collision>
      <origin xyz="4.33681e-19 0 0" rpy="3.14159 3.26186e-36 -4.9299e-32"/>
      <geometry>
        <mesh filename="package://assets/part_1.stl"/>
      </geometry>
    </collision>
    <!-- Part composant4_3 -->
    <visual>
      <origin xyz="4.33681e-18 6.93889e-18 0.0684" rpy="-1.88738e-15 -1.5708 0"/>
      <geometry>
        <mesh filename="package://assets/composant4.stl"/>
      </geometry>
      <material name="composant4_3_material">
        <color rgba="0.952941 0.796078 0.486275 1"/>
      </material>
    </visual>
    <collision>
      <origin xyz="4.33681e-18 6.93889e-18 0.0684" rpy="-1.88738e-15 -1.5708 0"/>
      <geometry>
        <mesh filename="package://assets/composant4.stl"/>
      </geometry>
    </collision>
    <!-- Part vis_à_tête_tronconique_jis_b_1111___m3_x_4___h_acier_inoxydable_a2_standard_v1_3 -->
    <visual>
      <origin xyz="4.33681e-18 6.93889e-18 0.0684" rpy="-1.88738e-15 -1.5708 0"/>
      <geometry>
        <mesh filename="package://assets/vis_à_tête_tronconique_jis_b_1111___m3_x_4___h_acier_inoxydable_a2_standard_v1.stl"/>
      </geometry>
      <material name="vis_à_tête_tronconique_jis_b_1111___m3_x_4___h_acier_inoxydable_a2_standard_v1_3_material">
        <color rgba="0.796078 0.796078 0.796078 1"/>
      </material>
    </visual>
    <collision>
      <origin xyz="4.33681e-18 6.93889e-18 0.0684" rpy="-1.88738e-15 -1.5708 0"/>
      <geometry>
        <mesh filename="package://assets/vis_à_tête_tronconique_jis_b_1111___m3_x_4___h_acier_inoxydable_a2_standard_v1.stl"/>
      </geometry>
    </collision>
    <!-- Part vis_3 -->
    <visual>
      <origin xyz="4.33681e-18 6.93889e-18 0.0684" rpy="-1.88738e-15 -1.5708 0"/>
      <geometry>
        <mesh filename="package://assets/vis.stl"/>
      </geometry>
      <material name="vis_3_material">
        <color rgba="0.0980392 0.0980392 0.0980392 1"/>
      </material>
    </visual>
    <collision>
      <origin xyz="4.33681e-18 6.93889e-18 0.0684" rpy="-1.88738e-15 -1.5708 0"/>
      <geometry>
        <mesh filename="package://assets/vis.stl"/>
      </geometry>
    </collision>
    <!-- Part composant3_3 -->
    <visual>
      <origin xyz="4.33681e-18 6.93889e-18 0.0684" rpy="-1.88738e-15 -1.5708 0"/>
      <geometry>
        <mesh filename="package://assets/composant3.stl"/>
      </geometry>
      <material name="composant3_3_material">
        <color rgba="0.960784 0.960784 0.964706 1"/>
      </material>
    </visual>
    <collision>
      <origin xyz="4.33681e-18 6.93889e-18 0.0684" rpy="-1.88738e-15 -1.5708 0"/>
      <geometry>
        <mesh filename="package://assets/composant3.stl"/>
      </geometry>
    </collision>
    <!-- Part vis_1_3 -->
    <visual>
      <origin xyz="4.33681e-18 6.93889e-18 0.0684" rpy="-1.88738e-15 -1.5708 0"/>
      <geometry>
        <mesh filename="package://assets/vis_1.stl"/>
      </geometry>
      <material name="vis_1_3_material">
        <color rgba="0.0980392 0.0980392 0.0980392 1"/>
      </material>
    </visual>
    <collision>
      <origin xyz="4.33681e-18 6.93889e-18 0.0684" rpy="-1.88738e-15 -1.5708 0"/>
      <geometry>
        <mesh filename="package://assets/vis_1.stl"/>
      </geometry>
    </collision>
    <!-- Part composant2_3 -->
    <visual>
      <origin xyz="4.33681e-18 6.93889e-18 0.0684" rpy="-1.88738e-15 -1.5708 0"/>
      <geometry>
        <mesh filename="package://assets/composant2.stl"/>
      </geometry>
      <material name="composant2_3_material">
        <color rgba="0.960784 0.960784 0.964706 1"/>
      </material>
    </visual>
    <collision>
      <origin xyz="4.33681e-18 6.93889e-18 0.0684" rpy="-1.88738e-15 -1.5708 0"/>
      <geometry>
        <mesh filename="package://assets/composant2.stl"/>
      </geometry>
    </collision>
    <!-- Part servo_motor_sts3215_v10_3 -->
    <visual>
      <origin xyz="4.33681e-18 6.93889e-18 0.0684" rpy="-1.88738e-15 -1.5708 0"/>
      <geometry>
        <mesh filename="package://assets/servo_motor_sts3215_v10.stl"/>
      </geometry>
      <material name="servo_motor_sts3215_v10_3_material">
        <color rgba="0.247059 0.247059 0.247059 1"/>
      </material>
    </visual>
    <collision>
      <origin xyz="4.33681e-18 6.93889e-18 0.0684" rpy="-1.88738e-15 -1.5708 0"/>
      <geometry>
        <mesh filename="package://assets/servo_motor_sts3215_v10.stl"/>
      </geometry>
    </collision>
  </link>
  <!-- Link servo_holder_2_right -->
  <link name="servo_holder_2_right">
    <inertial>
      <origin xyz="-0.0581183 0.000675022 0.0200448" rpy="0 0 0"/>
      <mass value="0.102324"/>
      <inertia ixx="4.10674e-05" ixy="-1.76403e-06" ixz="2.82895e-06" iyy="7.91302e-05" iyz="2.86127e-07" izz="5.08509e-05"/>
    </inertial>
    <!-- Part servo_holder_2_right -->
    <visual>
      <origin xyz="0.100812 -0.0182 0.0234473" rpy="1.5708 -0.104008 4.67811e-32"/>
      <geometry>
        <mesh filename="package://assets/servo_holder_2_right.stl"/>
      </geometry>
      <material name="servo_holder_2_right_material">
        <color rgba="0.262745 0.282353 0.301961 1"/>
      </material>
    </visual>
    <collision>
      <origin xyz="0.100812 -0.0182 0.0234473" rpy="1.5708 -0.104008 4.67811e-32"/>
      <geometry>
        <mesh filename="package://assets/servo_holder_2_right.stl"/>
      </geometry>
    </collision>
    <!-- Part composant4_4 -->
    <visual>
      <origin xyz="-0.0689457 1.59595e-16 0.0349006" rpy="3.14159 -1.5708 0"/>
      <geometry>
        <mesh filename="package://assets/composant4.stl"/>
      </geometry>
      <material name="composant4_4_material">
        <color rgba="0.952941 0.796078 0.486275 1"/>
      </material>
    </visual>
    <collision>
      <origin xyz="-0.0689457 1.59595e-16 0.0349006" rpy="3.14159 -1.5708 0"/>
      <geometry>
        <mesh filename="package://assets/composant4.stl"/>
      </geometry>
    </collision>
    <!-- Part vis_à_tête_tronconique_jis_b_1111___m3_x_4___h_acier_inoxydable_a2_standard_v1_4 -->
    <visual>
      <origin xyz="-0.0689457 1.59595e-16 0.0349006" rpy="3.14159 -1.5708 0"/>
      <geometry>
        <mesh filename="package://assets/vis_à_tête_tronconique_jis_b_1111___m3_x_4___h_acier_inoxydable_a2_standard_v1.stl"/>
      </geometry>
      <material name="vis_à_tête_tronconique_jis_b_1111___m3_x_4___h_acier_inoxydable_a2_standard_v1_4_material">
        <color rgba="0.796078 0.796078 0.796078 1"/>
      </material>
    </visual>
    <collision>
      <origin xyz="-0.0689457 1.59595e-16 0.0349006" rpy="3.14159 -1.5708 0"/>
      <geometry>
        <mesh filename="package://assets/vis_à_tête_tronconique_jis_b_1111___m3_x_4___h_acier_inoxydable_a2_standard_v1.stl"/>
      </geometry>
    </collision>
    <!-- Part vis_4 -->
    <visual>
      <origin xyz="-0.0689457 1.59595e-16 0.0349006" rpy="3.14159 -1.5708 0"/>
      <geometry>
        <mesh filename="package://assets/vis.stl"/>
      </geometry>
      <material name="vis_4_material">
        <color rgba="0.0980392 0.0980392 0.0980392 1"/>
      </material>
    </visual>
    <collision>
      <origin xyz="-0.0689457 1.59595e-16 0.0349006" rpy="3.14159 -1.5708 0"/>
      <geometry>
        <mesh filename="package://assets/vis.stl"/>
      </geometry>
    </collision>
    <!-- Part composant3_4 -->
    <visual>
      <origin xyz="-0.0689457 1.59595e-16 0.0349006" rpy="3.14159 -1.5708 0"/>
      <geometry>
        <mesh filename="package://assets/composant3.stl"/>
      </geometry>
      <material name="composant3_4_material">
        <color rgba="0.960784 0.960784 0.964706 1"/>
      </material>
    </visual>
    <collision>
      <origin xyz="-0.0689457 1.59595e-16 0.0349006" rpy="3.14159 -1.5708 0"/>
      <geometry>
        <mesh filename="package://assets/composant3.stl"/>
      </geometry>
    </collision>
    <!-- Part vis_1_4 -->
    <visual>
      <origin xyz="-0.0689457 1.59595e-16 0.0349006" rpy="3.14159 -1.5708 0"/>
      <geometry>
        <mesh filename="package://assets/vis_1.stl"/>
      </geometry>
      <material name="vis_1_4_material">
        <color rgba="0.0980392 0.0980392 0.0980392 1"/>
      </material>
    </visual>
    <collision>
      <origin xyz="-0.0689457 1.59595e-16 0.0349006" rpy="3.14159 -1.5708 0"/>
      <geometry>
        <mesh filename="package://assets/vis_1.stl"/>
      </geometry>
    </collision>
    <!-- Part composant2_4 -->
    <visual>
      <origin xyz="-0.0689457 1.59595e-16 0.0349006" rpy="3.14159 -1.5708 0"/>
      <geometry>
        <mesh filename="package://assets/composant2.stl"/>
      </geometry>
      <material name="composant2_4_material">
        <color rgba="0.960784 0.960784 0.964706 1"/>
      </material>
    </visual>
    <collision>
      <origin xyz="-0.0689457 1.59595e-16 0.0349006" rpy="3.14159 -1.5708 0"/>
      <geometry>
        <mesh filename="package://assets/composant2.stl"/>
      </geometry>
    </collision>
    <!-- Part servo_motor_sts3215_v10_4 -->
    <visual>
      <origin xyz="-0.0689457 1.59595e-16 0.0349006" rpy="3.14159 -1.5708 0"/>
      <geometry>
        <mesh filename="package://assets/servo_motor_sts3215_v10.stl"/>
      </geometry>
      <material name="servo_motor_sts3215_v10_4_material">
        <color rgba="0.247059 0.247059 0.247059 1"/>
      </material>
    </visual>
    <collision>
      <origin xyz="-0.0689457 1.59595e-16 0.0349006" rpy="3.14159 -1.5708 0"/>
      <geometry>
        <mesh filename="package://assets/servo_motor_sts3215_v10.stl"/>
      </geometry>
    </collision>
  </link>
  <!-- Link servo_holder_4 -->
  <link name="servo_holder_4">
    <inertial>
      <origin xyz="0.0559692 1.42113e-08 0.0177128" rpy="0 0 0"/>
      <mass value="0.0728745"/>
      <inertia ixx="1.98198e-05" ixy="-1.12362e-11" ixz="4.90018e-07" iyy="5.95513e-05" iyz="-1.0947e-11" izz="4.798e-05"/>
    </inertial>
    <!-- Part servo_holder_4 -->
    <visual>
      <origin xyz="6.93889e-18 0 0.0364" rpy="9.06201e-32 3.86891e-32 -2.93199e-31"/>
      <geometry>
        <mesh filename="package://assets/servo_holder_4.stl"/>
      </geometry>
      <material name="servo_holder_4_material">
        <color rgba="0.301961 0.301961 0.301961 1"/>
      </material>
    </visual>
    <collision>
      <origin xyz="6.93889e-18 0 0.0364" rpy="9.06201e-32 3.86891e-32 -2.93199e-31"/>
      <geometry>
        <mesh filename="package://assets/servo_holder_4.stl"/>
      </geometry>
    </collision>
    <!-- Part composant4_5 -->
    <visual>
      <origin xyz="0.0732925 6.93889e-18 0.0185244" rpy="3.14159 5.65575e-31 -7.7777e-31"/>
      <geometry>
        <mesh filename="package://assets/composant4.stl"/>
      </geometry>
      <material name="composant4_5_material">
        <color rgba="0.952941 0.796078 0.486275 1"/>
      </material>
    </visual>
    <collision>
      <origin xyz="0.0732925 6.93889e-18 0.0185244" rpy="3.14159 5.65575e-31 -7.7777e-31"/>
      <geometry>
        <mesh filename="package://assets/composant4.stl"/>
      </geometry>
    </collision>
    <!-- Part vis_à_tête_tronconique_jis_b_1111___m3_x_4___h_acier_inoxydable_a2_standard_v1_5 -->
    <visual>
      <origin xyz="0.0732925 6.93889e-18 0.0185244" rpy="3.14159 5.65575e-31 -7.7777e-31"/>
      <geometry>
        <mesh filename="package://assets/vis_à_tête_tronconique_jis_b_1111___m3_x_4___h_acier_inoxydable_a2_standard_v1.stl"/>
      </geometry>
      <material name="vis_à_tête_tronconique_jis_b_1111___m3_x_4___h_acier_inoxydable_a2_standard_v1_5_material">
        <color rgba="0.796078 0.796078 0.796078 1"/>
      </material>
    </visual>
    <collision>
      <origin xyz="0.0732925 6.93889e-18 0.0185244" rpy="3.14159 5.65575e-31 -7.7777e-31"/>
      <geometry>
        <mesh filename="package://assets/vis_à_tête_tronconique_jis_b_1111___m3_x_4___h_acier_inoxydable_a2_standard_v1.stl"/>
      </geometry>
    </collision>
    <!-- Part vis_5 -->
    <visual>
      <origin xyz="0.0732925 6.93889e-18 0.0185244" rpy="3.14159 5.65575e-31 -7.7777e-31"/>
      <geometry>
        <mesh filename="package://assets/vis.stl"/>
      </geometry>
      <material name="vis_5_material">
        <color rgba="0.0980392 0.0980392 0.0980392 1"/>
      </material>
    </visual>
    <collision>
      <origin xyz="0.0732925 6.93889e-18 0.0185244" rpy="3.14159 5.65575e-31 -7.7777e-31"/>
      <geometry>
        <mesh filename="package://assets/vis.stl"/>
      </geometry>
    </collision>
    <!-- Part composant3_5 -->
    <visual>
      <origin xyz="0.0732925 6.93889e-18 0.0185244" rpy="3.14159 5.65575e-31 -7.7777e-31"/>
      <geometry>
        <mesh filename="package://assets/composant3.stl"/>
      </geometry>
      <material name="composant3_5_material">
        <color rgba="0.960784 0.960784 0.964706 1"/>
      </material>
    </visual>
    <collision>
      <origin xyz="0.0732925 6.93889e-18 0.0185244" rpy="3.14159 5.65575e-31 -7.7777e-31"/>
      <geometry>
        <mesh filename="package://assets/composant3.stl"/>
      </geometry>
    </collision>
    <!-- Part vis_1_5 -->
    <visual>
      <origin xyz="0.0732925 6.93889e-18 0.0185244" rpy="3.14159 5.65575e-31 -7.7777e-31"/>
      <geometry>
        <mesh filename="package://assets/vis_1.stl"/>
      </geometry>
      <material name="vis_1_5_material">
        <color rgba="0.0980392 0.0980392 0.0980392 1"/>
      </material>
    </visual>
    <collision>
      <origin xyz="0.0732925 6.93889e-18 0.0185244" rpy="3.14159 5.65575e-31 -7.7777e-31"/>
      <geometry>
        <mesh filename="package://assets/vis_1.stl"/>
      </geometry>
    </collision>
    <!-- Part composant2_5 -->
    <visual>
      <origin xyz="0.0732925 6.93889e-18 0.0185244" rpy="3.14159 5.65575e-31 -7.7777e-31"/>
      <geometry>
        <mesh filename="package://assets/composant2.stl"/>
      </geometry>
      <material name="composant2_5_material">
        <color rgba="0.960784 0.960784 0.964706 1"/>
      </material>
    </visual>
    <collision>
      <origin xyz="0.0732925 6.93889e-18 0.0185244" rpy="3.14159 5.65575e-31 -7.7777e-31"/>
      <geometry>
        <mesh filename="package://assets/composant2.stl"/>
      </geometry>
    </collision>
    <!-- Part servo_motor_sts3215_v10_5 -->
    <visual>
      <origin xyz="0.0732925 6.93889e-18 0.0185244" rpy="3.14159 5.65575e-31 -7.7777e-31"/>
      <geometry>
        <mesh filename="package://assets/servo_motor_sts3215_v10.stl"/>
      </geometry>
      <material name="servo_motor_sts3215_v10_5_material">
        <color rgba="0.247059 0.247059 0.247059 1"/>
      </material>
    </visual>
    <collision>
      <origin xyz="0.0732925 6.93889e-18 0.0185244" rpy="3.14159 5.65575e-31 -7.7777e-31"/>
      <geometry>
        <mesh filename="package://assets/servo_motor_sts3215_v10.stl"/>
      </geometry>
    </collision>
  </link>
  <!-- Link servo_holder_4_2 -->
  <link name="servo_holder_4_2">
    <inertial>
      <origin xyz="0.0559692 1.42113e-08 0.0177128" rpy="0 0 0"/>
      <mass value="0.0728745"/>
      <inertia ixx="1.98198e-05" ixy="-1.12362e-11" ixz="4.90018e-07" iyy="5.95513e-05" iyz="-1.0947e-11" izz="4.798e-05"/>
    </inertial>
    <!-- Part servo_holder_4_2 -->
    <visual>
      <origin xyz="3.46945e-18 0 0.0364" rpy="5.56809e-32 5.24827e-34 -8.67175e-33"/>
      <geometry>
        <mesh filename="package://assets/servo_holder_4.stl"/>
      </geometry>
      <material name="servo_holder_4_2_material">
        <color rgba="0.301961 0.301961 0.301961 1"/>
      </material>
    </visual>
    <collision>
      <origin xyz="3.46945e-18 0 0.0364" rpy="5.56809e-32 5.24827e-34 -8.67175e-33"/>
      <geometry>
        <mesh filename="package://assets/servo_holder_4.stl"/>
      </geometry>
    </collision>
    <!-- Part composant4_6 -->
    <visual>
      <origin xyz="0.0732925 6.93889e-18 0.0185244" rpy="3.14159 1.73983e-31 -1.10908e-32"/>
      <geometry>
        <mesh filename="package://assets/composant4.stl"/>
      </geometry>
      <material name="composant4_6_material">
        <color rgba="0.952941 0.796078 0.486275 1"/>
      </material>
    </visual>
    <collision>
      <origin xyz="0.0732925 6.93889e-18 0.0185244" rpy="3.14159 1.73983e-31 -1.10908e-32"/>
      <geometry>
        <mesh filename="package://assets/composant4.stl"/>
      </geometry>
    </collision>
    <!-- Part vis_à_tête_tronconique_jis_b_1111___m3_x_4___h_acier_inoxydable_a2_standard_v1_6 -->
    <visual>
      <origin xyz="0.0732925 6.93889e-18 0.0185244" rpy="3.14159 1.73983e-31 -1.10908e-32"/>
      <geometry>
        <mesh filename="package://assets/vis_à_tête_tronconique_jis_b_1111___m3_x_4___h_acier_inoxydable_a2_standard_v1.stl"/>
      </geometry>
      <material name="vis_à_tête_tronconique_jis_b_1111___m3_x_4___h_acier_inoxydable_a2_standard_v1_6_material">
        <color rgba="0.796078 0.796078 0.796078 1"/>
      </material>
    </visual>
    <collision>
      <origin xyz="0.0732925 6.93889e-18 0.0185244" rpy="3.14159 1.73983e-31 -1.10908e-32"/>
      <geometry>
        <mesh filename="package://assets/vis_à_tête_tronconique_jis_b_1111___m3_x_4___h_acier_inoxydable_a2_standard_v1.stl"/>
      </geometry>
    </collision>
    <!-- Part vis_6 -->
    <visual>
      <origin xyz="0.0732925 6.93889e-18 0.0185244" rpy="3.14159 1.73983e-31 -1.10908e-32"/>
      <geometry>
        <mesh filename="package://assets/vis.stl"/>
      </geometry>
      <material name="vis_6_material">
        <color rgba="0.0980392 0.0980392 0.0980392 1"/>
      </material>
    </visual>
    <collision>
      <origin xyz="0.0732925 6.93889e-18 0.0185244" rpy="3.14159 1.73983e-31 -1.10908e-32"/>
      <geometry>
        <mesh filename="package://assets/vis.stl"/>
      </geometry>
    </collision>
    <!-- Part composant3_6 -->
    <visual>
      <origin xyz="0.0732925 6.93889e-18 0.0185244" rpy="3.14159 1.73983e-31 -1.10908e-32"/>
      <geometry>
        <mesh filename="package://assets/composant3.stl"/>
      </geometry>
      <material name="composant3_6_material">
        <color rgba="0.960784 0.960784 0.964706 1"/>
      </material>
    </visual>
    <collision>
      <origin xyz="0.0732925 6.93889e-18 0.0185244" rpy="3.14159 1.73983e-31 -1.10908e-32"/>
      <geometry>
        <mesh filename="package://assets/composant3.stl"/>
      </geometry>
    </collision>
    <!-- Part vis_1_6 -->
    <visual>
      <origin xyz="0.0732925 6.93889e-18 0.0185244" rpy="3.14159 1.73983e-31 -1.10908e-32"/>
      <geometry>
        <mesh filename="package://assets/vis_1.stl"/>
      </geometry>
      <material name="vis_1_6_material">
        <color rgba="0.0980392 0.0980392 0.0980392 1"/>
      </material>
    </visual>
    <collision>
      <origin xyz="0.0732925 6.93889e-18 0.0185244" rpy="3.14159 1.73983e-31 -1.10908e-32"/>
      <geometry>
        <mesh filename="package://assets/vis_1.stl"/>
      </geometry>
    </collision>
    <!-- Part composant2_6 -->
    <visual>
      <origin xyz="0.0732925 6.93889e-18 0.0185244" rpy="3.14159 1.73983e-31 -1.10908e-32"/>
      <geometry>
        <mesh filename="package://assets/composant2.stl"/>
      </geometry>
      <material name="composant2_6_material">
        <color rgba="0.960784 0.960784 0.964706 1"/>
      </material>
    </visual>
    <collision>
      <origin xyz="0.0732925 6.93889e-18 0.0185244" rpy="3.14159 1.73983e-31 -1.10908e-32"/>
      <geometry>
        <mesh filename="package://assets/composant2.stl"/>
      </geometry>
    </collision>
    <!-- Part servo_motor_sts3215_v10_6 -->
    <visual>
      <origin xyz="0.0732925 6.93889e-18 0.0185244" rpy="3.14159 1.73983e-31 -1.10908e-32"/>
      <geometry>
        <mesh filename="package://assets/servo_motor_sts3215_v10.stl"/>
      </geometry>
      <material name="servo_motor_sts3215_v10_6_material">
        <color rgba="0.247059 0.247059 0.247059 1"/>
      </material>
    </visual>
    <collision>
      <origin xyz="0.0732925 6.93889e-18 0.0185244" rpy="3.14159 1.73983e-31 -1.10908e-32"/>
      <geometry>
        <mesh filename="package://assets/servo_motor_sts3215_v10.stl"/>
      </geometry>
    </collision>
  </link>
  <!-- Link cushion_right -->
  <link name="cushion_right">
    <inertial>
      <origin xyz="-0.0194706 -0.0420367 0.0158895" rpy="0 0 0"/>
      <mass value="0.191143"/>
      <inertia ixx="6.61931e-05" ixy="-3.74292e-06" ixz="-1.39333e-06" iyy="0.000224241" iyz="9.58456e-06" izz="0.00023826"/>
    </inertial>
    <!-- Part cushion_right -->
    <visual>
      <origin xyz="0 -0.0516163 0.132131" rpy="-1.5708 -1.5708 0"/>
      <geometry>
        <mesh filename="package://assets/cushion_right.stl"/>
      </geometry>
      <material name="cushion_right_material">
        <color rgba="0 0 0 1"/>
      </material>
    </visual>
    <collision>
      <origin xyz="0 -0.0516163 0.132131" rpy="-1.5708 -1.5708 0"/>
      <geometry>
        <mesh filename="package://assets/cushion_right.stl"/>
      </geometry>
    </collision>
    <!-- Part foot_right -->
    <visual>
      <origin xyz="0 -0.0516163 0.132131" rpy="-1.5708 -1.5708 0"/>
      <geometry>
        <mesh filename="package://assets/foot_right.stl"/>
      </geometry>
      <material name="foot_right_material">
        <color rgba="0.917647 0.917647 0.917647 1"/>
      </material>
    </visual>
    <collision>
      <origin xyz="0 -0.0516163 0.132131" rpy="-1.5708 -1.5708 0"/>
      <geometry>
        <mesh filename="package://assets/foot_right.stl"/>
      </geometry>
    </collision>
  </link>
  <!-- Joint from servo_holder_4_2 to cushion_right -->
  <joint name="Leg1_E" type="revolute">
    <origin xyz="0.0857926 1.21493e-05 -0.0001756" rpy="1.73983e-31 2.22308e-29 1.5708"/>
    <parent link="servo_holder_4_2"/>
    <child link="cushion_right"/>
    <axis xyz="0 0 1"/>
    <limit effort="2.686" velocity="9.01" lower="-3.141592653589793" upper="3.141592653589793"/>
  </joint>
  <!-- Joint from servo_holder_4 to servo_holder_4_2 -->
  <joint name="Leg1_D" type="revolute">
    <origin xyz="0.0857925 1.52656e-16 -0.0001756" rpy="-3.33067e-16 -6.66134e-16 2.55513e-30"/>
    <parent link="servo_holder_4"/>
    <child link="servo_holder_4_2"/>
    <axis xyz="0 0 1"/>
    <limit effort="2.686" velocity="9.01" lower="-3.141592653589793" upper="3.141592653589793"/>
  </joint>
  <!-- Joint from servo_holder_2_right to servo_holder_4 -->
  <joint name="Leg1_C" type="revolute">
    <origin xyz="-0.0866457 1.8735e-16 0.0474006" rpy="1.5708 -9.37968e-16 1.5708"/>
    <parent link="servo_holder_2_right"/>
    <child link="servo_holder_4"/>
    <axis xyz="0 0 1"/>
    <limit effort="2.686" velocity="9.01" lower="-3.141592653589793" upper="3.141592653589793"/>
  </joint>
  <!-- Joint from part_1 to servo_holder_2_right -->
  <joint name="Leg1_B" type="revolute">
    <origin xyz="0.0183 -1.38778e-17 0.0809" rpy="1.5708 3.33067e-16 -1.5708"/>
    <parent link="part_1"/>
    <child link="servo_holder_2_right"/>
    <axis xyz="0 0 1"/>
    <limit effort="2.686" velocity="9.01" lower="-3.141592653589793" upper="3.141592653589793"/>
  </joint>
  <!-- Joint from bottom_frame to part_1 -->
  <joint name="Leg1_A" type="revolute">
    <origin xyz="-0.0505 0.0037713 0.142433" rpy="-3.14159 1.58527e-19 -1.5708"/>
    <parent link="bottom_frame"/>
    <child link="part_1"/>
    <axis xyz="0 0 1"/>
    <limit effort="2.686" velocity="9.01" lower="-3.141592653589793" upper="3.141592653589793"/>
  </joint>
  <!-- Link part_1_2 -->
  <link name="part_1_2">
    <inertial>
      <origin xyz="0.00346141 -1.8868e-08 0.0528536" rpy="0 0 0"/>
      <mass value="0.0633736"/>
      <inertia ixx="3.87727e-05" ixy="1.75025e-11" ixz="8.67219e-06" iyy="4.53541e-05" iyz="-7.80749e-12" izz="1.32807e-05"/>
    </inertial>
    <!-- Part part_1_2 -->
    <visual>
      <origin xyz="4.33681e-19 0 0" rpy="3.14159 3.26186e-36 -4.9299e-32"/>
      <geometry>
        <mesh filename="package://assets/part_1.stl"/>
      </geometry>
      <material name="part_1_2_material">
        <color rgba="0.262745 0.282353 0.301961 1"/>
      </material>
    </visual>
    <collision>
      <origin xyz="4.33681e-19 0 0" rpy="3.14159 3.26186e-36 -4.9299e-32"/>
      <geometry>
        <mesh filename="package://assets/part_1.stl"/>
      </geometry>
    </collision>
    <!-- Part composant4_7 -->
    <visual>
      <origin xyz="4.33681e-18 6.93889e-18 0.06575" rpy="-1.88738e-15 -1.5708 0"/>
      <geometry>
        <mesh filename="package://assets/composant4.stl"/>
      </geometry>
      <material name="composant4_7_material">
        <color rgba="0.952941 0.796078 0.486275 1"/>
      </material>
    </visual>
    <collision>
      <origin xyz="4.33681e-18 6.93889e-18 0.06575" rpy="-1.88738e-15 -1.5708 0"/>
      <geometry>
        <mesh filename="package://assets/composant4.stl"/>
      </geometry>
    </collision>
    <!-- Part vis_à_tête_tronconique_jis_b_1111___m3_x_4___h_acier_inoxydable_a2_standard_v1_7 -->
    <visual>
      <origin xyz="4.33681e-18 6.93889e-18 0.06575" rpy="-1.88738e-15 -1.5708 0"/>
      <geometry>
        <mesh filename="package://assets/vis_à_tête_tronconique_jis_b_1111___m3_x_4___h_acier_inoxydable_a2_standard_v1.stl"/>
      </geometry>
      <material name="vis_à_tête_tronconique_jis_b_1111___m3_x_4___h_acier_inoxydable_a2_standard_v1_7_material">
        <color rgba="0.796078 0.796078 0.796078 1"/>
      </material>
    </visual>
    <collision>
      <origin xyz="4.33681e-18 6.93889e-18 0.06575" rpy="-1.88738e-15 -1.5708 0"/>
      <geometry>
        <mesh filename="package://assets/vis_à_tête_tronconique_jis_b_1111___m3_x_4___h_acier_inoxydable_a2_standard_v1.stl"/>
      </geometry>
    </collision>
    <!-- Part vis_7 -->
    <visual>
      <origin xyz="4.33681e-18 6.93889e-18 0.06575" rpy="-1.88738e-15 -1.5708 0"/>
      <geometry>
        <mesh filename="package://assets/vis.stl"/>
      </geometry>
      <material name="vis_7_material">
        <color rgba="0.0980392 0.0980392 0.0980392 1"/>
      </material>
    </visual>
    <collision>
      <origin xyz="4.33681e-18 6.93889e-18 0.06575" rpy="-1.88738e-15 -1.5708 0"/>
      <geometry>
        <mesh filename="package://assets/vis.stl"/>
      </geometry>
    </collision>
    <!-- Part composant3_7 -->
    <visual>
      <origin xyz="4.33681e-18 6.93889e-18 0.06575" rpy="-1.88738e-15 -1.5708 0"/>
      <geometry>
        <mesh filename="package://assets/composant3.stl"/>
      </geometry>
      <material name="composant3_7_material">
        <color rgba="0.960784 0.960784 0.964706 1"/>
      </material>
    </visual>
    <collision>
      <origin xyz="4.33681e-18 6.93889e-18 0.06575" rpy="-1.88738e-15 -1.5708 0"/>
      <geometry>
        <mesh filename="package://assets/composant3.stl"/>
      </geometry>
    </collision>
    <!-- Part vis_1_7 -->
    <visual>
      <origin xyz="4.33681e-18 6.93889e-18 0.06575" rpy="-1.88738e-15 -1.5708 0"/>
      <geometry>
        <mesh filename="package://assets/vis_1.stl"/>
      </geometry>
      <material name="vis_1_7_material">
        <color rgba="0.0980392 0.0980392 0.0980392 1"/>
      </material>
    </visual>
    <collision>
      <origin xyz="4.33681e-18 6.93889e-18 0.06575" rpy="-1.88738e-15 -1.5708 0"/>
      <geometry>
        <mesh filename="package://assets/vis_1.stl"/>
      </geometry>
    </collision>
    <!-- Part composant2_7 -->
    <visual>
      <origin xyz="4.33681e-18 6.93889e-18 0.06575" rpy="-1.88738e-15 -1.5708 0"/>
      <geometry>
        <mesh filename="package://assets/composant2.stl"/>
      </geometry>
      <material name="composant2_7_material">
        <color rgba="0.960784 0.960784 0.964706 1"/>
      </material>
    </visual>
    <collision>
      <origin xyz="4.33681e-18 6.93889e-18 0.06575" rpy="-1.88738e-15 -1.5708 0"/>
      <geometry>
        <mesh filename="package://assets/composant2.stl"/>
      </geometry>
    </collision>
    <!-- Part servo_motor_sts3215_v10_7 -->
    <visual>
      <origin xyz="4.33681e-18 6.93889e-18 0.06575" rpy="-1.88738e-15 -1.5708 0"/>
      <geometry>
        <mesh filename="package://assets/servo_motor_sts3215_v10.stl"/>
      </geometry>
      <material name="servo_motor_sts3215_v10_7_material">
        <color rgba="0.247059 0.247059 0.247059 1"/>
      </material>
    </visual>
    <collision>
      <origin xyz="4.33681e-18 6.93889e-18 0.06575" rpy="-1.88738e-15 -1.5708 0"/>
      <geometry>
        <mesh filename="package://assets/servo_motor_sts3215_v10.stl"/>
      </geometry>
    </collision>
  </link>
  <!-- Link servo_holder_2_left -->
  <link name="servo_holder_2_left">
    <inertial>
      <origin xyz="0.0581183 0.000675008 0.0200448" rpy="0 0 0"/>
      <mass value="0.102324"/>
      <inertia ixx="4.10674e-05" ixy="1.76407e-06" ixz="-2.82895e-06" iyy="7.91302e-05" iyz="2.86171e-07" izz="5.08509e-05"/>
    </inertial>
    <!-- Part servo_holder_2_left -->
    <visual>
      <origin xyz="-6.93889e-18 -0.0182 0.0182" rpy="1.5708 8.50471e-32 1.34453e-32"/>
      <geometry>
        <mesh filename="package://assets/servo_holder_2_left.stl"/>
      </geometry>
      <material name="servo_holder_2_left_material">
        <color rgba="0.262745 0.282353 0.301961 1"/>
      </material>
    </visual>
    <collision>
      <origin xyz="-6.93889e-18 -0.0182 0.0182" rpy="1.5708 8.50471e-32 1.34453e-32"/>
      <geometry>
        <mesh filename="package://assets/servo_holder_2_left.stl"/>
      </geometry>
    </collision>
    <!-- Part composant4_8 -->
    <visual>
      <origin xyz="0.0689457 1.38778e-17 0.0349006" rpy="-3.33067e-16 -1.5708 0"/>
      <geometry>
        <mesh filename="package://assets/composant4.stl"/>
      </geometry>
      <material name="composant4_8_material">
        <color rgba="0.952941 0.796078 0.486275 1"/>
      </material>
    </visual>
    <collision>
      <origin xyz="0.0689457 1.38778e-17 0.0349006" rpy="-3.33067e-16 -1.5708 0"/>
      <geometry>
        <mesh filename="package://assets/composant4.stl"/>
      </geometry>
    </collision>
    <!-- Part vis_à_tête_tronconique_jis_b_1111___m3_x_4___h_acier_inoxydable_a2_standard_v1_8 -->
    <visual>
      <origin xyz="0.0689457 1.38778e-17 0.0349006" rpy="-3.33067e-16 -1.5708 0"/>
      <geometry>
        <mesh filename="package://assets/vis_à_tête_tronconique_jis_b_1111___m3_x_4___h_acier_inoxydable_a2_standard_v1.stl"/>
      </geometry>
      <material name="vis_à_tête_tronconique_jis_b_1111___m3_x_4___h_acier_inoxydable_a2_standard_v1_8_material">
        <color rgba="0.796078 0.796078 0.796078 1"/>
      </material>
    </visual>
    <collision>
      <origin xyz="0.0689457 1.38778e-17 0.0349006" rpy="-3.33067e-16 -1.5708 0"/>
      <geometry>
        <mesh filename="package://assets/vis_à_tête_tronconique_jis_b_1111___m3_x_4___h_acier_inoxydable_a2_standard_v1.stl"/>
      </geometry>
    </collision>
    <!-- Part vis_8 -->
    <visual>
      <origin xyz="0.0689457 1.38778e-17 0.0349006" rpy="-3.33067e-16 -1.5708 0"/>
      <geometry>
        <mesh filename="package://assets/vis.stl"/>
      </geometry>
      <material name="vis_8_material">
        <color rgba="0.0980392 0.0980392 0.0980392 1"/>
      </material>
    </visual>
    <collision>
      <origin xyz="0.0689457 1.38778e-17 0.0349006" rpy="-3.33067e-16 -1.5708 0"/>
      <geometry>
        <mesh filename="package://assets/vis.stl"/>
      </geometry>
    </collision>
    <!-- Part composant3_8 -->
    <visual>
      <origin xyz="0.0689457 1.38778e-17 0.0349006" rpy="-3.33067e-16 -1.5708 0"/>
      <geometry>
        <mesh filename="package://assets/composant3.stl"/>
      </geometry>
      <material name="composant3_8_material">
        <color rgba="0.960784 0.960784 0.964706 1"/>
      </material>
    </visual>
    <collision>
      <origin xyz="0.0689457 1.38778e-17 0.0349006" rpy="-3.33067e-16 -1.5708 0"/>
      <geometry>
        <mesh filename="package://assets/composant3.stl"/>
      </geometry>
    </collision>
    <!-- Part vis_1_8 -->
    <visual>
      <origin xyz="0.0689457 1.38778e-17 0.0349006" rpy="-3.33067e-16 -1.5708 0"/>
      <geometry>
        <mesh filename="package://assets/vis_1.stl"/>
      </geometry>
      <material name="vis_1_8_material">
        <color rgba="0.0980392 0.0980392 0.0980392 1"/>
      </material>
    </visual>
    <collision>
      <origin xyz="0.0689457 1.38778e-17 0.0349006" rpy="-3.33067e-16 -1.5708 0"/>
      <geometry>
        <mesh filename="package://assets/vis_1.stl"/>
      </geometry>
    </collision>
    <!-- Part composant2_8 -->
    <visual>
      <origin xyz="0.0689457 1.38778e-17 0.0349006" rpy="-3.33067e-16 -1.5708 0"/>
      <geometry>
        <mesh filename="package://assets/composant2.stl"/>
      </geometry>
      <material name="composant2_8_material">
        <color rgba="0.960784 0.960784 0.964706 1"/>
      </material>
    </visual>
    <collision>
      <origin xyz="0.0689457 1.38778e-17 0.0349006" rpy="-3.33067e-16 -1.5708 0"/>
      <geometry>
        <mesh filename="package://assets/composant2.stl"/>
      </geometry>
    </collision>
    <!-- Part servo_motor_sts3215_v10_8 -->
    <visual>
      <origin xyz="0.0689457 1.38778e-17 0.0349006" rpy="-3.33067e-16 -1.5708 0"/>
      <geometry>
        <mesh filename="package://assets/servo_motor_sts3215_v10.stl"/>
      </geometry>
      <material name="servo_motor_sts3215_v10_8_material">
        <color rgba="0.247059 0.247059 0.247059 1"/>
      </material>
    </visual>
    <collision>
      <origin xyz="0.0689457 1.38778e-17 0.0349006" rpy="-3.33067e-16 -1.5708 0"/>
      <geometry>
        <mesh filename="package://assets/servo_motor_sts3215_v10.stl"/>
      </geometry>
    </collision>
  </link>
  <!-- Link servo_holder_4_3 -->
  <link name="servo_holder_4_3">
    <inertial>
      <origin xyz="0.0559692 1.42113e-08 0.0177128" rpy="0 0 0"/>
      <mass value="0.0728745"/>
      <inertia ixx="1.98198e-05" ixy="-1.12362e-11" ixz="4.90018e-07" iyy="5.95513e-05" iyz="-1.0947e-11" izz="4.798e-05"/>
    </inertial>
    <!-- Part servo_holder_4_3 -->
    <visual>
      <origin xyz="0 0 0.0364" rpy="-9.75507e-34 5.20495e-43 -1.09448e-33"/>
      <geometry>
        <mesh filename="package://assets/servo_holder_4.stl"/>
      </geometry>
      <material name="servo_holder_4_3_material">
        <color rgba="0.301961 0.301961 0.301961 1"/>
      </material>
    </visual>
    <collision>
      <origin xyz="0 0 0.0364" rpy="-9.75507e-34 5.20495e-43 -1.09448e-33"/>
      <geometry>
        <mesh filename="package://assets/servo_holder_4.stl"/>
      </geometry>
    </collision>
    <!-- Part composant4_9 -->
    <visual>
      <origin xyz="0.0732925 0 0.0185244" rpy="3.14159 5.20495e-43 -1.09448e-33"/>
      <geometry>
        <mesh filename="package://assets/composant4.stl"/>
      </geometry>
      <material name="composant4_9_material">
        <color rgba="0.952941 0.796078 0.486275 1"/>
      </material>
    </visual>
    <collision>
      <origin xyz="0.0732925 0 0.0185244" rpy="3.14159 5.20495e-43 -1.09448e-33"/>
      <geometry>
        <mesh filename="package://assets/composant4.stl"/>
      </geometry>
    </collision>
    <!-- Part vis_à_tête_tronconique_jis_b_1111___m3_x_4___h_acier_inoxydable_a2_standard_v1_9 -->
    <visual>
      <origin xyz="0.0732925 0 0.0185244" rpy="3.14159 5.20495e-43 -1.09448e-33"/>
      <geometry>
        <mesh filename="package://assets/vis_à_tête_tronconique_jis_b_1111___m3_x_4___h_acier_inoxydable_a2_standard_v1.stl"/>
      </geometry>
      <material name="vis_à_tête_tronconique_jis_b_1111___m3_x_4___h_acier_inoxydable_a2_standard_v1_9_material">
        <color rgba="0.796078 0.796078 0.796078 1"/>
      </material>
    </visual>
    <collision>
      <origin xyz="0.0732925 0 0.0185244" rpy="3.14159 5.20495e-43 -1.09448e-33"/>
      <geometry>
        <mesh filename="package://assets/vis_à_tête_tronconique_jis_b_1111___m3_x_4___h_acier_inoxydable_a2_standard_v1.stl"/>
      </geometry>
    </collision>
    <!-- Part vis_9 -->
    <visual>
      <origin xyz="0.0732925 0 0.0185244" rpy="3.14159 5.20495e-43 -1.09448e-33"/>
      <geometry>
        <mesh filename="package://assets/vis.stl"/>
      </geometry>
      <material name="vis_9_material">
        <color rgba="0.0980392 0.0980392 0.0980392 1"/>
      </material>
    </visual>
    <collision>
      <origin xyz="0.0732925 0 0.0185244" rpy="3.14159 5.20495e-43 -1.09448e-33"/>
      <geometry>
        <mesh filename="package://assets/vis.stl"/>
      </geometry>
    </collision>
    <!-- Part composant3_9 -->
    <visual>
      <origin xyz="0.0732925 0 0.0185244" rpy="3.14159 5.20495e-43 -1.09448e-33"/>
      <geometry>
        <mesh filename="package://assets/composant3.stl"/>
      </geometry>
      <material name="composant3_9_material">
        <color rgba="0.960784 0.960784 0.964706 1"/>
      </material>
    </visual>
    <collision>
      <origin xyz="0.0732925 0 0.0185244" rpy="3.14159 5.20495e-43 -1.09448e-33"/>
      <geometry>
        <mesh filename="package://assets/composant3.stl"/>
      </geometry>
    </collision>
    <!-- Part vis_1_9 -->
    <visual>
      <origin xyz="0.0732925 0 0.0185244" rpy="3.14159 5.20495e-43 -1.09448e-33"/>
      <geometry>
        <mesh filename="package://assets/vis_1.stl"/>
      </geometry>
      <material name="vis_1_9_material">
        <color rgba="0.0980392 0.0980392 0.0980392 1"/>
      </material>
    </visual>
    <collision>
      <origin xyz="0.0732925 0 0.0185244" rpy="3.14159 5.20495e-43 -1.09448e-33"/>
      <geometry>
        <mesh filename="package://assets/vis_1.stl"/>
      </geometry>
    </collision>
    <!-- Part composant2_9 -->
    <visual>
      <origin xyz="0.0732925 0 0.0185244" rpy="3.14159 5.20495e-43 -1.09448e-33"/>
      <geometry>
        <mesh filename="package://assets/composant2.stl"/>
      </geometry>
      <material name="composant2_9_material">
        <color rgba="0.960784 0.960784 0.964706 1"/>
      </material>
    </visual>
    <collision>
      <origin xyz="0.0732925 0 0.0185244" rpy="3.14159 5.20495e-43 -1.09448e-33"/>
      <geometry>
        <mesh filename="package://assets/composant2.stl"/>
      </geometry>
    </collision>
    <!-- Part servo_motor_sts3215_v10_9 -->
    <visual>
      <origin xyz="0.0732925 0 0.0185244" rpy="3.14159 5.20495e-43 -1.09448e-33"/>
      <geometry>
        <mesh filename="package://assets/servo_motor_sts3215_v10.stl"/>
      </geometry>
      <material name="servo_motor_sts3215_v10_9_material">
        <color rgba="0.247059 0.247059 0.247059 1"/>
      </material>
    </visual>
    <collision>
      <origin xyz="0.0732925 0 0.0185244" rpy="3.14159 5.20495e-43 -1.09448e-33"/>
      <geometry>
        <mesh filename="package://assets/servo_motor_sts3215_v10.stl"/>
      </geometry>
    </collision>
  </link>
  <!-- Link servo_holder_4_4 -->
  <link name="servo_holder_4_4">
    <inertial>
      <origin xyz="0.0559692 1.42113e-08 0.0177128" rpy="0 0 0"/>
      <mass value="0.0728745"/>
      <inertia ixx="1.98198e-05" ixy="-1.12362e-11" ixz="4.90018e-07" iyy="5.95513e-05" iyz="-1.0947e-11" izz="4.798e-05"/>
    </inertial>
    <!-- Part servo_holder_4_4 -->
    <visual>
      <origin xyz="0 0 0.0364" rpy="-9.75507e-34 5.20495e-43 -1.09448e-33"/>
      <geometry>
        <mesh filename="package://assets/servo_holder_4.stl"/>
      </geometry>
      <material name="servo_holder_4_4_material">
        <color rgba="0.301961 0.301961 0.301961 1"/>
      </material>
    </visual>
    <collision>
      <origin xyz="0 0 0.0364" rpy="-9.75507e-34 5.20495e-43 -1.09448e-33"/>
      <geometry>
        <mesh filename="package://assets/servo_holder_4.stl"/>
      </geometry>
    </collision>
    <!-- Part composant4_10 -->
    <visual>
      <origin xyz="0.0732925 1.38778e-17 0.0185244" rpy="3.14159 -3.99854e-29 3.33067e-16"/>
      <geometry>
        <mesh filename="package://assets/composant4.stl"/>
      </geometry>
      <material name="composant4_10_material">
        <color rgba="0.952941 0.796078 0.486275 1"/>
      </material>
    </visual>
    <collision>
      <origin xyz="0.0732925 1.38778e-17 0.0185244" rpy="3.14159 -3.99854e-29 3.33067e-16"/>
      <geometry>
        <mesh filename="package://assets/composant4.stl"/>
      </geometry>
    </collision>
    <!-- Part vis_à_tête_tronconique_jis_b_1111___m3_x_4___h_acier_inoxydable_a2_standard_v1_10 -->
    <visual>
      <origin xyz="0.0732925 1.38778e-17 0.0185244" rpy="3.14159 -3.99854e-29 3.33067e-16"/>
      <geometry>
        <mesh filename="package://assets/vis_à_tête_tronconique_jis_b_1111___m3_x_4___h_acier_inoxydable_a2_standard_v1.stl"/>
      </geometry>
      <material name="vis_à_tête_tronconique_jis_b_1111___m3_x_4___h_acier_inoxydable_a2_standard_v1_10_material">
        <color rgba="0.796078 0.796078 0.796078 1"/>
      </material>
    </visual>
    <collision>
      <origin xyz="0.0732925 1.38778e-17 0.0185244" rpy="3.14159 -3.99854e-29 3.33067e-16"/>
      <geometry>
        <mesh filename="package://assets/vis_à_tête_tronconique_jis_b_1111___m3_x_4___h_acier_inoxydable_a2_standard_v1.stl"/>
      </geometry>
    </collision>
    <!-- Part vis_10 -->
    <visual>
      <origin xyz="0.0732925 1.38778e-17 0.0185244" rpy="3.14159 -3.99854e-29 3.33067e-16"/>
      <geometry>
        <mesh filename="package://assets/vis.stl"/>
      </geometry>
      <material name="vis_10_material">
        <color rgba="0.0980392 0.0980392 0.0980392 1"/>
      </material>
    </visual>
    <collision>
      <origin xyz="0.0732925 1.38778e-17 0.0185244" rpy="3.14159 -3.99854e-29 3.33067e-16"/>
      <geometry>
        <mesh filename="package://assets/vis.stl"/>
      </geometry>
    </collision>
    <!-- Part composant3_10 -->
    <visual>
      <origin xyz="0.0732925 1.38778e-17 0.0185244" rpy="3.14159 -3.99854e-29 3.33067e-16"/>
      <geometry>
        <mesh filename="package://assets/composant3.stl"/>
      </geometry>
      <material name="composant3_10_material">
        <color rgba="0.960784 0.960784 0.964706 1"/>
      </material>
    </visual>
    <collision>
      <origin xyz="0.0732925 1.38778e-17 0.0185244" rpy="3.14159 -3.99854e-29 3.33067e-16"/>
      <geometry>
        <mesh filename="package://assets/composant3.stl"/>
      </geometry>
    </collision>
    <!-- Part vis_1_10 -->
    <visual>
      <origin xyz="0.0732925 1.38778e-17 0.0185244" rpy="3.14159 -3.99854e-29 3.33067e-16"/>
      <geometry>
        <mesh filename="package://assets/vis_1.stl"/>
      </geometry>
      <material name="vis_1_10_material">
        <color rgba="0.0980392 0.0980392 0.0980392 1"/>
      </material>
    </visual>
    <collision>
      <origin xyz="0.0732925 1.38778e-17 0.0185244" rpy="3.14159 -3.99854e-29 3.33067e-16"/>
      <geometry>
        <mesh filename="package://assets/vis_1.stl"/>
      </geometry>
    </collision>
    <!-- Part composant2_10 -->
    <visual>
      <origin xyz="0.0732925 1.38778e-17 0.0185244" rpy="3.14159 -3.99854e-29 3.33067e-16"/>
      <geometry>
        <mesh filename="package://assets/composant2.stl"/>
      </geometry>
      <material name="composant2_10_material">
        <color rgba="0.960784 0.960784 0.964706 1"/>
      </material>
    </visual>
    <collision>
      <origin xyz="0.0732925 1.38778e-17 0.0185244" rpy="3.14159 -3.99854e-29 3.33067e-16"/>
      <geometry>
        <mesh filename="package://assets/composant2.stl"/>
      </geometry>
    </collision>
    <!-- Part servo_motor_sts3215_v10_10 -->
    <visual>
      <origin xyz="0.0732925 1.38778e-17 0.0185244" rpy="3.14159 -3.99854e-29 3.33067e-16"/>
      <geometry>
        <mesh filename="package://assets/servo_motor_sts3215_v10.stl"/>
      </geometry>
      <material name="servo_motor_sts3215_v10_10_material">
        <color rgba="0.247059 0.247059 0.247059 1"/>
      </material>
    </visual>
    <collision>
      <origin xyz="0.0732925 1.38778e-17 0.0185244" rpy="3.14159 -3.99854e-29 3.33067e-16"/>
      <geometry>
        <mesh filename="package://assets/servo_motor_sts3215_v10.stl"/>
      </geometry>
    </collision>
  </link>
  <!-- Link cushion_left -->
  <link name="cushion_left">
    <inertial>
      <origin xyz="-0.0194706 0.0420367 0.0158895" rpy="0 0 0"/>
      <mass value="0.191143"/>
      <inertia ixx="6.6193e-05" ixy="3.74292e-06" ixz="-1.39334e-06" iyy="0.000224241" iyz="-9.58455e-06" izz="0.00023826"/>
    </inertial>
    <!-- Part foot_left -->
    <visual>
      <origin xyz="6.93889e-18 0.0516163 0.0390687" rpy="1.5708 1.5708 0"/>
      <geometry>
        <mesh filename="package://assets/foot_left.stl"/>
      </geometry>
      <material name="foot_left_material">
        <color rgba="0.917647 0.917647 0.917647 1"/>
      </material>
    </visual>
    <collision>
      <origin xyz="6.93889e-18 0.0516163 0.0390687" rpy="1.5708 1.5708 0"/>
      <geometry>
        <mesh filename="package://assets/foot_left.stl"/>
      </geometry>
    </collision>
    <!-- Part cushion_left -->
    <visual>
      <origin xyz="6.93889e-18 0.0516163 0.0390687" rpy="1.5708 1.5708 0"/>
      <geometry>
        <mesh filename="package://assets/cushion_left.stl"/>
      </geometry>
      <material name="cushion_left_material">
        <color rgba="0 0 0 1"/>
      </material>
    </visual>
    <collision>
      <origin xyz="6.93889e-18 0.0516163 0.0390687" rpy="1.5708 1.5708 0"/>
      <geometry>
        <mesh filename="package://assets/cushion_left.stl"/>
      </geometry>
    </collision>
  </link>
  <!-- Joint from servo_holder_4_4 to cushion_left -->
  <joint name="Leg2_E" type="revolute">
    <origin xyz="0.0857925 -7.63278e-17 -0.0001756" rpy="3.99854e-29 -2.62445e-31 -1.5708"/>
    <parent link="servo_holder_4_4"/>
    <child link="cushion_left"/>
    <axis xyz="0 0 1"/>
    <limit effort="2.686" velocity="9.01" lower="-3.141592653589793" upper="3.141592653589793"/>
  </joint>
  <!-- Joint from servo_holder_4_3 to servo_holder_4_4 -->
  <joint name="Leg2_D" type="revolute">
    <origin xyz="0.0857925 0 -0.0001756" rpy="-9.75507e-34 5.20495e-43 -1.09448e-33"/>
    <parent link="servo_holder_4_3"/>
    <child link="servo_holder_4_4"/>
    <axis xyz="0 0 1"/>
    <limit effort="2.686" velocity="9.01" lower="-3.141592653589793" upper="3.141592653589793"/>
  </joint>
  <!-- Joint from servo_holder_2_left to servo_holder_4_3 -->
  <joint name="Leg2_C" type="revolute">
    <origin xyz="0.0866457 2.77556e-17 0.0474006" rpy="-1.5708 6.12323e-17 1.5708"/>
    <parent link="servo_holder_2_left"/>
    <child link="servo_holder_4_3"/>
    <axis xyz="0 0 1"/>
    <limit effort="2.686" velocity="9.01" lower="-3.141592653589793" upper="3.141592653589793"/>
  </joint>
  <!-- Joint from part_1_2 to servo_holder_2_left -->
  <joint name="Leg2_B" type="revolute">
    <origin xyz="0.0177 -2.77556e-17 0.07825" rpy="1.5708 3.33067e-16 -1.5708"/>
    <parent link="part_1_2"/>
    <child link="servo_holder_2_left"/>
    <axis xyz="0 0 1"/>
    <limit effort="2.686" velocity="9.01" lower="-3.141592653589793" upper="3.141592653589793"/>
  </joint>
  <!-- Joint from bottom_frame to part_1_2 -->
  <joint name="Leg2_A" type="revolute">
    <origin xyz="0.0505 0.0037713 0.142433" rpy="-3.14159 1.58527e-19 -1.5708"/>
    <parent link="bottom_frame"/>
    <child link="part_1_2"/>
    <axis xyz="0 0 1"/>
    <limit effort="2.686" velocity="9.01" lower="-3.141592653589793" upper="3.141592653589793"/>
  </joint>
</robot>
